ERROR:flask.app:Exception on /home/save [POST]
Traceback (most recent call last):
  File "C:\Users\oboforty\AppData\Local\Programs\Python\Python37-32\lib\site-packages\flask\app.py", line 2292, in wsgi_app
    response = self.full_dispatch_request()
  File "C:\Users\oboforty\AppData\Local\Programs\Python\Python37-32\lib\site-packages\flask\app.py", line 1815, in full_dispatch_request
    rv = self.handle_user_exception(e)
  File "C:\Users\oboforty\AppData\Local\Programs\Python\Python37-32\lib\site-packages\flask\app.py", line 1718, in handle_user_exception
    reraise(exc_type, exc_value, tb)
  File "C:\Users\oboforty\AppData\Local\Programs\Python\Python37-32\lib\site-packages\flask\_compat.py", line 35, in reraise
    raise value
  File "C:\Users\oboforty\AppData\Local\Programs\Python\Python37-32\lib\site-packages\flask\app.py", line 1813, in full_dispatch_request
    rv = self.dispatch_request()
  File "C:\Users\oboforty\AppData\Local\Programs\Python\Python37-32\lib\site-packages\flask\app.py", line 1799, in dispatch_request
    return self.view_functions[rule.endpoint](**req.view_args)
  File "D:\dev\geopoly\generator\GeoEditor\controllers\HomeController.py", line 21, in post_save
    os.rename('public/geojson/map_combined.geojson', 'public/geojson/backup/{}.geojson'.format(now))
NameError: name 'os' is not defined
ERROR:flask.app:Exception on /home/save [POST]
Traceback (most recent call last):
  File "C:\Users\oboforty\AppData\Local\Programs\Python\Python37-32\lib\site-packages\flask\app.py", line 2292, in wsgi_app
    response = self.full_dispatch_request()
  File "C:\Users\oboforty\AppData\Local\Programs\Python\Python37-32\lib\site-packages\flask\app.py", line 1815, in full_dispatch_request
    rv = self.handle_user_exception(e)
  File "C:\Users\oboforty\AppData\Local\Programs\Python\Python37-32\lib\site-packages\flask\app.py", line 1718, in handle_user_exception
    reraise(exc_type, exc_value, tb)
  File "C:\Users\oboforty\AppData\Local\Programs\Python\Python37-32\lib\site-packages\flask\_compat.py", line 35, in reraise
    raise value
  File "C:\Users\oboforty\AppData\Local\Programs\Python\Python37-32\lib\site-packages\flask\app.py", line 1813, in full_dispatch_request
    rv = self.dispatch_request()
  File "C:\Users\oboforty\AppData\Local\Programs\Python\Python37-32\lib\site-packages\flask\app.py", line 1799, in dispatch_request
    return self.view_functions[rule.endpoint](**req.view_args)
  File "D:\dev\geopoly\generator\GeoEditor\controllers\HomeController.py", line 21, in post_save
    os.rename('public/geojson/map_combined.geojson', 'public/geojson/backup/{}.geojson'.format(now))
NameError: name 'os' is not defined
